Workbook

Sheet Cover
B2: Anthropic, PBC (ANT, proposed Nasdaq) — Investment model, pre-IPO
B3: Sameer Ahmed | valuation date 29 Oct 2026 | $ in millions unless noted | PUBLIC VERSION: comps sourced as noted
B5: Purpose
B6: A pre-IPO valuation of Anthropic from its preliminary S-1 (filed 26 Oct 2026), blending three methods: a 10-year FCFF DCF built on Aswath Damodaran's structure, a probability-weighted scenario value, and a relative value on comparable price-to-sales.
B8: How the toggles work
B9: Assumptions!C3 selects whose inputs drive the "User" blocks: Sameer, AD or User. Sameer's column is locked and always feeds the Sameer valuation, so his number does not move when others play with the User column. Valuation Summary shows Sameer, AD and User side by side against the reported offer range.
B11: Colour legend
B12: Blue = hardcoded input. Yellow = cells meant to be changed (User column, weights, probabilities). Light blue = Sameer's locked inputs. Orange = a Sameer input that differs from AD, with the reason beside it. Black = formula. Green = link to another tab.
B14: Tabs
B15: Valuation Summary · Assumptions · Standard Template · DCF · Scenario · Relative Valuation · Sensitivity · Charts · Sources
B17: Validation
B18: With AD selected, the AD block of the DCF reproduces his published $1,475,879m equity value and $447.34 per share to the dollar (DCF!C row "Value of equity", AD block). Bull/Bear blocks reproduce his post's cases within 1–4%.
... B24: Personal work from public filings. Not investment advice and not the view of any employer.

Sheet Valuation Summary
B2: Anthropic (ANT) — Valuation Summary & Blended Equity Value
B3: Cross-method blend | equity value in $bn | Sameer's column is locked; AD and User move with their inputs
B5: Reference pricing (reported offer range)
B6: Low | C6: 1500 | D6: $bn. Range as reported in the press and cited by AD; not in the S-1.
B7: Mid | C7: 1750
B8: High | C8: 2000
B10: Method | C10: Weight (Sameer) | D10: Weight (User) | E10: Sameer ($bn) | F10: AD ($bn) | G10: User ($bn) | H10: Sameer, weighted | I10: User, weighted | J10: Why this weight
B11: DCF (intrinsic) | C11: 0.4 | D11: 0.4 | E11: =IFERROR(DCF!$C$27/1000,"pending") -> 1364.748 | F11: =IFERROR(DCF!$C$63/1000,"pending") -> 1475.8784 | G11: =IFERROR(DCF!$C$99/1000,"pending") -> 1364.748 | H11: =IF(ISNUMBER(E11),C11*E11,0) -> 545.89918 | I11: =IF(ISNUMBER(G11),D11*G11,0) -> 545.89918 | J11: Primary: the only method that prices the commitments and the failure risk explicitly.
B12: Scenario (probability-weighted) | C12: 0.3 | D12: 0.3 | E12: =IFERROR(Scenario!$E$10/1000,"pending") -> 1604.1845 | F12: =IFERROR(Scenario!$F$10/1000,"pending") -> 1659.7497 | G12: =IFERROR(Scenario!$G$10/1000,"pending") -> 1604.1845 | H12: =IF(ISNUMBER(E12),C12*E12,0) -> 481.25534 | I12: =IF(ISNUMBER(G12),D12*G12,0) -> 481.25534 | J12: Forces the bear case into the number instead of leaving it as a footnote.
B13: Relative (comp P/S × NTM revenue) | C13: 0.3 | D13: 0.3 | E13: =IFERROR('Relative Valuation'!$C$19/1000,"pending") -> 1171.7351 | F13: =IFERROR('Relative Valuation'!$D$19/1000,"pending") -> 1225.2444 | G13: =IFERROR('Relative Valuation'!$E$19/1000,"pending") -> 1171.7351 | H13: =IF(ISNUMBER(E13),C13*E13,0) -> 351.52053 | I13: =IF(ISNUMBER(G13),D13*G13,0) -> 351.52053 | J13: Anchors to what the market pays for scaled AI revenue today.
B14: Effective weight sum (methods with a number) | H14: =SUMPRODUCT(C11:C13,--ISNUMBER(E11:E13)) -> 1 | I14: =SUMPRODUCT(D11:D13,--ISNUMBER(G11:G13)) -> 1
B15: Blended equity value ($bn) = Σ weighted ÷ effective weight | H15: =IF(H14>0,SUM(H11:H13)/H14,"n/a") -> 1378.6751 | I15: =IF(I14>0,SUM(I11:I13)/I14,"n/a") -> 1378.6751
B16: Weight check (Sameer / User must = 100%) | C16: =SUM(C11:C13) -> 1 | D16: =SUM(D11:D13) -> 1 | E16: =IF(AND(ROUND(C16,4)=1,ROUND(D16,4)=1),"OK","FIX WEIGHTS") -> OK
B19: Comparison ($bn) | C19: Value
B20: Sameer blended | C20: =H15 -> 1378.6751
B21: Sameer DCF | C21: =E11 -> 1364.748
B22: AD DCF (published) | C22: =F11 -> 1475.8784
B23: User blended | C23: =I15 -> 1378.6751
B24: Offer low | C24: =C6 -> 1500
B25: Offer mid | C25: =C7 -> 1750
B26: Offer high | C26: =C8 -> 2000
B28: Implied vs offer mid: Sameer blended | C28: =IFERROR(C20/C25-1,"n/a") -> -0.21218568
B29: Sameer's view
B30: Base-case value sits at or below the bottom of the reported range on every method. Buy below the blended value; above the mid-point of the range, sit out (AD's conclusion, reached independently here). The post-conversion share count and the June 2026 commitments table, both blank in the preliminary S-1, are the two disclosures that would move this most.

Sheet Assumptions
B2: Assumptions — one row per driver; sub-drivers indented; every number carries its reason
B3: Whose inputs drive the User blocks? | C3: User | E3: Sameer's column is locked: it always feeds the Sameer valuation regardless of this switch.
B5: Driver | C5: Sameer (locked) | D5: AD (published) | E5: User (toggle) | F5: Bull (AD best) | G5: Bear (AD worst) | H5: Active | I5: Unit | J5: Sameer's reason | K5: AD's reason
B6: LTM revenue to 30 Jun 2026 | C6: 19708 | D6: 20608 | E6: 19708 | F6: 20608 | G6: 20608 | H6: =INDEX(C6:E6,MATCH($C$3,{"Sameer","AD","User"},0)) -> 19708 | I6: $m | J6: FY2025 4,585 − H1 2025 1,163 + H1 2026 16,286 = 19,708, all from the S-1 statements of operations. AD's cell reads 5,485 for FY2025; that is a transposition. | K6: Entered as =5485-1163+16286 in his sheet.
B7: Revenue growth, year 1 (2027E) | C7: 4 | D7: 4 | E7: 4 | F7: 4 | G7: 4 | H7: =INDEX(C7:E7,MATCH($C$3,{"Sameer","AD","User"},0)) -> 4 | I7: % | J7: Q2 2026 revenue of $11.6bn annualises to $46bn; Q2 grew 144% on Q1. 400% on the LTM base gives 2027E revenue of ~$99bn, roughly 2x the current run-rate. Consistent with the S-1's statement that 2026 revenue grew 1,368% y/y in Q2. | K7: "Reflects updated ARR estimates."
B8: Revenue CAGR, years 2–5 | C8: 0.42 | D8: 0.42 | E8: 0.42 | F8: 0.5125 | G8: 0.09 | H8: =INDEX(C8:E8,MATCH($C$3,{"Sameer","AD","User"},0)) -> 0.42 | I8: % | J8: Reaches ~$1tn of revenue by 2036 on AD's path. Justified by the S-1 demand data: ≥$100k customers 950 → 11,900 in a year, NRR disclosed, 79% of revenue now outside the top five. The lever to challenge first; see Sensitivity. | K8: Focus on the 2036 revenue target (~$1tn, "AI as industry player" market of $5tn+); the CAGR "is just an input".
B9: Operating margin, year 1 | C9: 0.05 | D9: 0.05 | E9: 0.05 | F9: 0.05 | G9: 0.05 | H9: =INDEX(C9:E9,MATCH($C$3,{"Sameer","AD","User"},0)) -> 0.05 | I9: % | J9: Q2 2026 GAAP operating margin was 8.4% after $1.26bn SBC; H1 was (4)%. 5% is the midpoint of a year in which $321bn of leases start billing. | K9: "Operating margins in 3rd quarter inched toward +ve."
B10: Premium-product revenue share, long run | C10: 0.75 | D10: 0.75 | E10: 0.75 | F10: 1 | G10: 0 | H10: =INDEX(C10:E10,MATCH($C$3,{"Sameer","AD","User"},0)) -> 0.75 | I10: % | J10: Sub-driver of target margin. S-1: enterprise, usage-based revenue is the substantial majority; >50% of ≥$100k customers use Platform plus a first-party app. | K10: 75% premium / 25% mass market end-mix.
B11: Premium-product operating margin | C11: 0.4 | D11: 0.4 | E11: 0.4 | F11: 0.4 | G11: 0.4 | H11: =INDEX(C11:E11,MATCH($C$3,{"Sameer","AD","User"},0)) -> 0.4 | I11: % | J11: Sub-driver. Top-quartile enterprise software margin (AD's benchmark); MSFT FY2026 GAAP operating margin was 46.8% for scale. | K11: "Close to 40% for the top quartile" of enterprise software.
B12: Mass-market operating margin | C12: 0.1 | D12: 0.1 | E12: 0.1 | F12: 0.1 | G12: 0.1 | H12: =INDEX(C12:E12,MATCH($C$3,{"Sameer","AD","User"},0)) -> 0.1 | I12: % | J12: Sub-driver. Business-services margin; consumer AI is subscription and ad-free today. | K12: Business services, roughly 10%.
B13: Regulatory drag on margin | C13: -0.05 | D13: -0.05 | E13: -0.05 | F13: 0 | G13: -0.15 | H13: =INDEX(C13:E13,MATCH($C$3,{"Sameer","AD","User"},0)) -> -0.05 | I13: % | J13: Sub-driver. S-1 lists the EU AI Act, US state laws and the Bartz settlement ($1.5bn) as live costs; minor restrictions is the base. Bear uses −15%. | K13: "Shave my initial operating margin estimate of 32.5% down to 27.5%".
B14: Target operating margin, year 5 on (calculated) | C14: =C10*C11+(1-C10)*C12+C13 -> 0.275 | D14: =D10*D11+(1-D10)*D12+D13 -> 0.275 | E14: =E10*E11+(1-E10)*E12+E13 -> 0.275 | F14: =F10*F11+(1-F10)*F12+F13 -> 0.4 | G14: =G10*G11+(1-G10)*G12+G13 -> -0.05 | H14: =INDEX(C14:E14,MATCH($C$3,{"Sameer","AD","User"},0)) -> 0.275 | I14: % | J14: Calculated: premium share × premium margin + (1 − share) × mass margin + regulatory drag. Not an input. | K14: 32.5% less 5% = 27.5%.
B15: Year margin converges | C15: 5 | D15: 5 | E15: 5 | F15: 5 | G15: 5 | H15: =INDEX(C15:E15,MATCH($C$3,{"Sameer","AD","User"},0)) -> 5 | I15: yr | J15: Linear path from year 1 to target by 2031E. Compute ratio fell from 177% to 48% of revenue in five quarters; five more years to reach 27.5% is not aggressive on that trend. | K15: Convergence in year 5 (default).
B16: Sales to capital, years 1–10 | C16: 2.5 | D16: 3 | E16: 2.5 | F16: 4 | G16: 1 | H16: =INDEX(C16:E16,MATCH($C$3,{"Sameer","AD","User"},0)) -> 2.5 | I16: x | J16: C3: compute costs high near term, ease later. The S-1 shows $321.4bn of leases executed but not commenced and $265.6bn of minimum purchase commitments at 30 June; the near-term capital intensity is contracted, not optional. 2.5 rather than AD's 3.0 costs ~$90bn of value. | K16: C4: "compute power costs ease near term"; invest $1 per $3 of new revenue, in line with tech companies.
B17: Cost of capital, years 1–5 | C17: 0.0974 | D17: 0.0974 | E17: 0.0974 | F17: 0.0779 | G17: 0.0988 | H17: =INDEX(C17:E17,MATCH($C$3,{"Sameer","AD","User"},0)) -> 0.0974 | I17: % | J17: Between the US median (9.16%) and third quartile (9.88%) at Sept 2026. Software risk plus a single-product, single-customer-type business. Second-order: ±1pt moves value ±15%. | K17: 9.74%, "among the least critical" inputs.
B18: Riskfree rate = terminal growth | C18: 0.049 | D18: 0.049 | E18: 0.049 | F18: 0.049 | G18: 0.049 | H18: =INDEX(C18:E18,MATCH($C$3,{"Sameer","AD","User"},0)) -> 0.049 | I18: % | J18: 10-year Treasury at the valuation date. Perpetual growth capped at the riskfree rate (AD's rule). | K18: 4.9%.
B19: Terminal cost of capital | C19: 0.0913 | D19: 0.0913 | E19: 0.0913 | F19: 0.0913 | G19: 0.0913 | H19: =INDEX(C19:E19,MATCH($C$3,{"Sameer","AD","User"},0)) -> 0.0913 | I19: % | J19: Riskfree + mature-market ERP (4.23%). Reached by year 10. | K19: AD default.
B20: Return on capital after year 10 | C20: 0.15 | D20: 0.15 | E20: 0.15 | F20: 0.15 | G20: 0.15 | H20: =INDEX(C20:E20,MATCH($C$3,{"Sameer","AD","User"},0)) -> 0.15 | I20: % | J20: Excess returns in perpetuity assume a moat. Kept at AD's 15% as base; Sensitivity shows 9.13% (no moat). | K20: 15%: long-lasting competitive advantages.
B21: Marginal tax rate by year 10 | C21: 0.25 | D21: 0.25 | E21: 0.25 | F21: 0.25 | G21: 0.25 | H21: =INDEX(C21:E21,MATCH($C$3,{"Sameer","AD","User"},0)) -> 0.25 | I21: % | J21: US federal + state. Effective rate is 0 now (NOLs); converges by year 10. | K21: 25%.
B22: Probability of failure | C22: 0.1 | D22: 0.1 | E22: 0.1 | F22: 0.1 | G22: 0.1 | H22: =INDEX(C22:E22,MATCH($C$3,{"Sameer","AD","User"},0)) -> 0.1 | I22: % | J22: $131bn cash and $77bn of undrawn facilities against a commitment schedule that bills before revenue arrives. 10% is a funding-gap probability, not a product-failure one. | K22: 10%, losing half the value if it happens.
B23: Value retained if it fails | C23: 0.5 | D23: 0.5 | E23: 0.5 | F23: 0.5 | G23: 0.5 | H23: =INDEX(C23:E23,MATCH($C$3,{"Sameer","AD","User"},0)) -> 0.5 | I23: % | J23: Model weights, data and brand have resale value; compute contracts are the liability. | K23: 50% of fair value.
B24: Debt on balance sheet | C24: 109316 | D24: 109316 | E24: 109316 | F24: 109316 | G24: 109316 | H24: =INDEX(C24:E24,MATCH($C$3,{"Sameer","AD","User"},0)) -> 109316 | I24: $m | J24: Convertible notes payable at fair value 108,566 + other noncurrent liabilities 750 (S-1 balance sheet, 30 Jun 2026). Principal is only 10,200; using fair value is conservative because the notes convert into the share count too. | K24: 108,566 + 750.
B25: PV of compute and lease commitments | C25: 363020 | D25: 363020 | E25: 363020 | F25: 363020 | G25: 363020 | H25: =INDEX(C25:E25,MATCH($C$3,{"Sameer","AD","User"},0)) -> 363020 | I25: $m | J25: AD's schedule (63,168 / 98,128 / 60,832 / 58,304 / 50,000 / 124,000 beyond) at 6.28%. The S-1's June 2026 table is blank; this is an estimate built from the $417bn subsequent-events figure and the Dec 2025 $54.6bn table. Replace on the S-1/A. | K25: PV of commitments "in excess of $600 billion".
B26: Cash and cash equivalents | C26: 112389 | D26: 112389 | E26: 112389 | F26: 112389 | G26: 112389 | H26: =INDEX(C26:E26,MATCH($C$3,{"Sameer","AD","User"},0)) -> 112389 | I26: $m | J26: S-1 balance sheet, 30 Jun 2026. Short-term investments (19,262) excluded, as AD did; adding them is +$19bn. | K26: 112,389.
... B31: Reference price per share | C31: 525 | D31: 525 | E31: 525 | F31: 525 | G31: 525 | H31: =INDEX(C31:E31,MATCH($C$3,{"Sameer","AD","User"},0)) -> 525 | I31: $ | J31: $1.75tn midpoint of the reported range ÷ AD's 3,298m post-IPO shares. | K31: $525 at $1.75 trillion.
B33: Orange = Sameer differs from AD (LTM revenue, sales-to-capital, options). Indented rows are sub-drivers of the target margin. Bull/Bear are AD's published cases and feed the Scenario tab only.

Sheet Standard Template
B2: Standard Template — Anthropic historicals from the S-1 and the User block forecast
B5: Field | C5: Segment | D5: 2023A | E5: 2024A | F5: 2025A | G5: H1 2025A | H5: H1 2026A | I5: 2027E | J5: 2028E | K5: 2029E | L5: 2030E | M5: 2031E | N5: 2032E | O5: 2033E | P5: 2034E | Q5: 2035E | R5: 2036E
B6: Revenue | D6: 41 | E6: 386 | F6: 4585 | G6: 1163 | H6: 16286 | I6: =DCF!D81 -> 98540 | J6: =DCF!E81 -> 139926.8 | K6: =DCF!F81 -> 198696.06 | L6: =DCF!G81 -> 282148.4 | M6: =DCF!H81 -> 400650.73 | N6: =DCF!I81 -> 539195.75 | O6: =DCF!J81 -> 685641.31 | P6: =DCF!K81 -> 820986.91 | ... R6: =DCF!M81 -> 967316.99
C7: % Growth | E7: =E6/D6-1 -> 8.4146341 | F7: =F6/E6-1 -> 10.878238 | H7: =H6/G6-1 -> 13.003439 | I7: =DCF!D80 -> 4 | J7: =DCF!E80 -> 0.42 | K7: =DCF!F80 -> 0.42 | L7: =DCF!G80 -> 0.42 | M7: =DCF!H80 -> 0.42 | N7: =DCF!I80 -> 0.3458 | O7: =DCF!J80 -> 0.2716 | P7: =DCF!K80 -> 0.1974 | ... R7: =DCF!M80 -> 0.049
B8: Compute and infrastructure | G8: 2334 | H8: 8945
C9: % of revenue | G9: =G8/G6 -> 2.0068788 | H9: =H8/H6 -> 0.54924475
B10: Operating income (loss) | D10: -551 | E10: -2980 | F10: -8060 | G10: -2135 | H10: -693 | I10: =DCF!D83 -> 4927 | J10: =DCF!E83 -> 19589.752 | K10: =DCF!F83 -> 36758.77 | L10: =DCF!G83 -> 64894.132 | M10: =DCF!H83 -> 110178.95 | N10: =DCF!I83 -> 148278.83 | O10: =DCF!J83 -> 188551.36 | P10: =DCF!K83 -> 225771.4 | ... R10: =DCF!M83 -> 266012.17
C11: % Margin | D11: =D10/D6 -> -13.439024 | E11: =E10/E6 -> -7.7202073 | F11: =F10/F6 -> -1.7579062 | G11: =G10/G6 -> -1.8357696 | H11: =H10/H6 -> -0.042551885 | I11: =DCF!D82 -> 0.05 | J11: =DCF!E82 -> 0.14 | K11: =DCF!F82 -> 0.185 | L11: =DCF!G82 -> 0.23 | M11: =DCF!H82 -> 0.275 | N11: =DCF!I82 -> 0.275 | O11: =DCF!J82 -> 0.275 | P11: =DCF!K82 -> 0.275 | ... R11: =DCF!M82 -> 0.275
B12: Net loss | D12: -1531 | E12: -8309 | F12: -41965 | G12: -12969 | H12: -80748
B13: Stock-based compensation | D13: 29 | E13: 192 | F13: 1165 | G13: 286 | H13: 2185
B14: Adjusted operating income (non-GAAP, filing) | D14: -522 | E14: -2788 | F14: -4854 | G14: -1849 | H14: 1618
B15: Net cash from operating activities | D15: -1627 | E15: -5692 | F15: -2637 | G15: -1513 | H15: 3929
B16: Purchases of property and equipment | D16: -2 | E16: -15 | F16: -131 | G16: -18 | H16: -482
B18: Quarterly (S-1 quarterly table), $m
B19: Field | D19: Q1 25 | E19: Q2 25 | F19: Q3 25 | G19: Q4 25 | H19: Q1 26 | I19: Q2 26
B20: Revenue | D20: 376 | E20: 787 | F20: 1382 | G20: 2040 | H20: 4731 | I20: 11555
C21: % q/q | E21: =E20/D20-1 -> 1.0930851 | F21: =F20/E20-1 -> 0.75603558 | G21: =G20/F20-1 -> 0.47612156 | H21: =H20/G20-1 -> 1.3191176 | I21: =I20/H20-1 -> 1.4424012
B22: Compute and infrastructure | D22: 944 | E22: 1390 | F22: 2047 | G22: 2945 | H22: 3387 | I22: 5558
C23: % of revenue | D23: =D22/D20 -> 2.5106383 | E23: =E22/E20 -> 1.7662008 | F23: =F22/F20 -> 1.4811867 | G23: =G22/G20 -> 1.4436275 | H23: =H22/H20 -> 0.7159163 | I23: =I22/I20 -> 0.48100389
B24: Personnel | D24: 218 | E24: 320 | F24: 489 | G24: 812 | H24: 1295 | I24: 1857
B25: Bartz settlement | D25: 0 | E25: 0 | F25: 1500 | G25: 0 | H25: 0 | I25: 0
B26: Sales, marketing and partnerships | D26: 24 | E26: 96 | F26: 202 | G26: 246 | H26: 1033 | I26: 2135
B27: Other operating and administrative | D27: 125 | E27: 181 | F27: 233 | G27: 873 | H27: 683 | I27: 1031
B28: Operating income (loss) | D28: -935 | E28: -1200 | F28: -3089 | G28: -2836 | H28: -1667 | I28: 974
C29: % margin | D29: =D28/D20 -> -2.4867021 | E29: =E28/E20 -> -1.5247776 | F29: =F28/F20 -> -2.2351664 | G29: =G28/G20 -> -1.3901961 | H29: =H28/H20 -> -0.3523568 | I29: =I28/I20 -> 0.084292514
B30: Interest income | D30: 51 | E30: 64 | F30: 124 | G30: 192 | H30: 349 | I30: 762
B31: Change in FV of convertible notes, derivative liabilities, SAFEs | D31: -5701 | E31: -5241 | F31: -9165 | G31: -14201 | H31: -12791 | I31: -59597
B32: Other income (expense), net | D32: 0 | E32: 0 | F32: -3 | G32: -5 | H32: -309 | I32: -8448
B33: Net loss | D33: -6592 | E33: -6377 | F33: -12138 | G33: -16858 | H33: -14439 | I33: -66309
B34: Stock-based compensation | D34: 105 | E34: 181 | F34: 305 | G34: 574 | H34: 924 | I34: 1261
B36: Source: Anthropic PBC Form S-1 (preliminary), filed 26 Oct 2026: statements of operations, cash flows, quarterly results table and non-GAAP reconciliation. Q2 2026 SBC = H1 2,185 − Q1 924 (calculated). Forecast columns follow the User block on the DCF tab.

Sheet DCF
B2: DCF — 10-year FCFF, failure-adjusted. One block per input set; Sameer's block is locked to his column.
B5: Sameer block (locked)
B6: $m | C6: Base | D6: 2027E | E6: 2028E | F6: 2029E | G6: 2030E | H6: 2031E | I6: 2032E | J6: 2033E | K6: 2034E | L6: 2035E | M6: 2036E | N6: Terminal
B7: t | D7: 1 | E7: 2 | F7: 3 | G7: 4 | H7: 5 | I7: 6 | J7: 7 | K7: 8 | L7: 9 | M7: 10
B8: Revenue growth | D8: =IF(D$7=1,Assumptions!$C$7,IF(D$7<=5,Assumptions!$C$8,Assumptions!$C$8-((Assumptions!$C$8-Assumptions!$C$18)/5)*(D$7-5))) -> 4 | E8: =IF(E$7=1,Assumptions!$C$7,IF(E$7<=5,Assumptions!$C$8,Assumptions!$C$8-((Assumptions!$C$8-Assumptions!$C$18)/5)*(E$7-5))) -> 0.42 | F8: =IF(F$7=1,Assumptions!$C$7,IF(F$7<=5,Assumptions!$C$8,Assumptions!$C$8-((Assumptions!$C$8-Assumptions!$C$18)/5)*(F$7-5))) -> 0.42 | G8: =IF(G$7=1,Assumptions!$C$7,IF(G$7<=5,Assumptions!$C$8,Assumptions!$C$8-((Assumptions!$C$8-Assumptions!$C$18)/5)*(G$7-5))) -> 0.42 | H8: =IF(H$7=1,Assumptions!$C$7,IF(H$7<=5,Assumptions!$C$8,Assumptions!$C$8-((Assumptions!$C$8-Assumptions!$C$18)/5)*(H$7-5))) -> 0.42 | I8: =IF(I$7=1,Assumptions!$C$7,IF(I$7<=5,Assumptions!$C$8,Assumptions!$C$8-((Assumptions!$C$8-Assumptions!$C$18)/5)*(I$7-5))) -> 0.3458 | J8: =IF(J$7=1,Assumptions!$C$7,IF(J$7<=5,Assumptions!$C$8,Assumptions!$C$8-((Assumptions!$C$8-Assumptions!$C$18)/5)*(J$7-5))) -> 0.2716 | K8: =IF(K$7=1,Assumptions!$C$7,IF(K$7<=5,Assumptions!$C$8,Assumptions!$C$8-((Assumptions!$C$8-Assumptions!$C$18)/5)*(K$7-5))) -> 0.1974 | ... M8: =IF(M$7=1,Assumptions!$C$7,IF(M$7<=5,Assumptions!$C$8,Assumptions!$C$8-((Assumptions!$C$8-Assumptions!$C$18)/5)*(M$7-5))) -> 0.049 | N8: =Assumptions!$C$18 -> 0.049
B9: Revenue | C9: =Assumptions!$C$6 -> 19708 | D9: =C9*(1+D8) -> 98540 | E9: =D9*(1+E8) -> 139926.8 | F9: =E9*(1+F8) -> 198696.06 | G9: =F9*(1+G8) -> 282148.4 | H9: =G9*(1+H8) -> 400650.73 | I9: =H9*(1+I8) -> 539195.75 | J9: =I9*(1+J8) -> 685641.31 | K9: =J9*(1+K8) -> 820986.91 | ... N9: =M9*(1+N8) -> 1014715.5
B10: Operating margin | D10: =IF(D$7=1,Assumptions!$C$9,IF(D$7>Assumptions!$C$15,Assumptions!$C$14,Assumptions!$C$14-((Assumptions!$C$14-Assumptions!$C$9)*(Assumptions!$C$15-D$7)/Assumptions!$C$15))) -> 0.05 | E10: =IF(E$7=1,Assumptions!$C$9,IF(E$7>Assumptions!$C$15,Assumptions!$C$14,Assumptions!$C$14-((Assumptions!$C$14-Assumptions!$C$9)*(Assumptions!$C$15-E$7)/Assumptions!$C$15))) -> 0.14 | F10: =IF(F$7=1,Assumptions!$C$9,IF(F$7>Assumptions!$C$15,Assumptions!$C$14,Assumptions!$C$14-((Assumptions!$C$14-Assumptions!$C$9)*(Assumptions!$C$15-F$7)/Assumptions!$C$15))) -> 0.185 | G10: =IF(G$7=1,Assumptions!$C$9,IF(G$7>Assumptions!$C$15,Assumptions!$C$14,Assumptions!$C$14-((Assumptions!$C$14-Assumptions!$C$9)*(Assumptions!$C$15-G$7)/Assumptions!$C$15))) -> 0.23 | H10: =IF(H$7=1,Assumptions!$C$9,IF(H$7>Assumptions!$C$15,Assumptions!$C$14,Assumptions!$C$14-((Assumptions!$C$14-Assumptions!$C$9)*(Assumptions!$C$15-H$7)/Assumptions!$C$15))) -> 0.275 | I10: =IF(I$7=1,Assumptions!$C$9,IF(I$7>Assumptions!$C$15,Assumptions!$C$14,Assumptions!$C$14-((Assumptions!$C$14-Assumptions!$C$9)*(Assumptions!$C$15-I$7)/Assumptions!$C$15))) -> 0.275 | J10: =IF(J$7=1,Assumptions!$C$9,IF(J$7>Assumptions!$C$15,Assumptions!$C$14,Assumptions!$C$14-((Assumptions!$C$14-Assumptions!$C$9)*(Assumptions!$C$15-J$7)/Assumptions!$C$15))) -> 0.275 | K10: =IF(K$7=1,Assumptions!$C$9,IF(K$7>Assumptions!$C$15,Assumptions!$C$14,Assumptions!$C$14-((Assumptions!$C$14-Assumptions!$C$9)*(Assumptions!$C$15-K$7)/Assumptions!$C$15))) -> 0.275 | ... M10: =IF(M$7=1,Assumptions!$C$9,IF(M$7>Assumptions!$C$15,Assumptions!$C$14,Assumptions!$C$14-((Assumptions!$C$14-Assumptions!$C$9)*(Assumptions!$C$15-M$7)/Assumptions!$C$15))) -> 0.275 | N10: =Assumptions!$C$14 -> 0.275
B11: EBIT | D11: =D9*D10 -> 4927 | E11: =E9*E10 -> 19589.752 | F11: =F9*F10 -> 36758.77 | G11: =G9*G10 -> 64894.132 | H11: =H9*H10 -> 110178.95 | I11: =I9*I10 -> 148278.83 | J11: =J9*J10 -> 188551.36 | K11: =K9*K10 -> 225771.4 | ... N11: =N9*N10 -> 279046.77
B12: Tax rate | D12: =IF(D$7<=5,0,Assumptions!$C$21*(D$7-5)/5) -> 0 | E12: =IF(E$7<=5,0,Assumptions!$C$21*(E$7-5)/5) -> 0 | F12: =IF(F$7<=5,0,Assumptions!$C$21*(F$7-5)/5) -> 0 | G12: =IF(G$7<=5,0,Assumptions!$C$21*(G$7-5)/5) -> 0 | H12: =IF(H$7<=5,0,Assumptions!$C$21*(H$7-5)/5) -> 0 | I12: =IF(I$7<=5,0,Assumptions!$C$21*(I$7-5)/5) -> 0.05 | J12: =IF(J$7<=5,0,Assumptions!$C$21*(J$7-5)/5) -> 0.1 | K12: =IF(K$7<=5,0,Assumptions!$C$21*(K$7-5)/5) -> 0.15 | ... M12: =IF(M$7<=5,0,Assumptions!$C$21*(M$7-5)/5) -> 0.25 | N12: =Assumptions!$C$21 -> 0.25
B13: EBIT(1−t) after NOL | D13: =IF(D11>0,IF(D11<C14,D11,D11-(D11-C14)*D12),D11) -> 4927 | E13: =IF(E11>0,IF(E11<D14,E11,E11-(E11-D14)*E12),E11) -> 19589.752 | F13: =IF(F11>0,IF(F11<E14,F11,F11-(F11-E14)*F12),F11) -> 36758.77 | G13: =IF(G11>0,IF(G11<F14,G11,G11-(G11-F14)*G12),G11) -> 64894.132 | H13: =IF(H11>0,IF(H11<G14,H11,H11-(H11-G14)*H12),H11) -> 110178.95 | I13: =IF(I11>0,IF(I11<H14,I11,I11-(I11-H14)*I12),I11) -> 140864.89 | J13: =IF(J11>0,IF(J11<I14,J11,J11-(J11-I14)*J12),J11) -> 169696.23 | K13: =IF(K11>0,IF(K11<J14,K11,K11-(K11-J14)*K12),K11) -> 191905.69 | ... M13: =IF(M11>0,IF(M11<L14,M11,M11-(M11-L14)*M12),M11) -> 199509.13 | N13: =N11*(1-N12) -> 209285.08
B14: NOL carried | C14: 0 | D14: =IF(D11<0,C14-D11,IF(C14>D11,C14-D11,0)) -> 0 | E14: =IF(E11<0,D14-E11,IF(D14>E11,D14-E11,0)) -> 0 | F14: =IF(F11<0,E14-F11,IF(E14>F11,E14-F11,0)) -> 0 | G14: =IF(G11<0,F14-G11,IF(F14>G11,F14-G11,0)) -> 0 | H14: =IF(H11<0,G14-H11,IF(G14>H11,G14-H11,0)) -> 0 | I14: =IF(I11<0,H14-I11,IF(H14>I11,H14-I11,0)) -> 0 | J14: =IF(J11<0,I14-J11,IF(I14>J11,I14-J11,0)) -> 0 | K14: =IF(K11<0,J14-K11,IF(J14>K11,J14-K11,0)) -> 0 | ... M14: =IF(M11<0,L14-M11,IF(L14>M11,L14-M11,0)) -> 0
B15: − Reinvestment = ΔRev ÷ S/C | D15: =(E9-D9)/Assumptions!$C$16 -> 16554.72 | E15: =(F9-E9)/Assumptions!$C$16 -> 23507.702 | F15: =(G9-F9)/Assumptions!$C$16 -> 33380.937 | G15: =(H9-G9)/Assumptions!$C$16 -> 47400.931 | H15: =(I9-H9)/Assumptions!$C$16 -> 55418.009 | I15: =(J9-I9)/Assumptions!$C$16 -> 58578.226 | J15: =(K9-J9)/Assumptions!$C$16 -> 54138.238 | K15: =(L9-K9)/Assumptions!$C$16 -> 40458.235 | ... M15: =(N9-M9)/Assumptions!$C$16 -> 18959.413 | N15: =IF(N8>0,(N8/Assumptions!$C$20)*N13,0) -> 68366.458
B16: FCFF | D16: =D13-D15 -> -11627.72 | E16: =E13-E15 -> -3917.9504 | F16: =F13-F15 -> 3377.833 | G16: =G13-G15 -> 17493.201 | H16: =H13-H15 -> 54760.941 | I16: =I13-I15 -> 82286.663 | J16: =J13-J15 -> 115557.99 | K16: =K13-K15 -> 151447.46 | ... N16: =N13-N15 -> 140918.62
B17: Cost of capital | D17: =IF(D$7<=5,Assumptions!$C$17,Assumptions!$C$17-((Assumptions!$C$17-Assumptions!$C$19)/5)*(D$7-5)) -> 0.0974 | E17: =IF(E$7<=5,Assumptions!$C$17,Assumptions!$C$17-((Assumptions!$C$17-Assumptions!$C$19)/5)*(E$7-5)) -> 0.0974 | F17: =IF(F$7<=5,Assumptions!$C$17,Assumptions!$C$17-((Assumptions!$C$17-Assumptions!$C$19)/5)*(F$7-5)) -> 0.0974 | G17: =IF(G$7<=5,Assumptions!$C$17,Assumptions!$C$17-((Assumptions!$C$17-Assumptions!$C$19)/5)*(G$7-5)) -> 0.0974 | H17: =IF(H$7<=5,Assumptions!$C$17,Assumptions!$C$17-((Assumptions!$C$17-Assumptions!$C$19)/5)*(H$7-5)) -> 0.0974 | I17: =IF(I$7<=5,Assumptions!$C$17,Assumptions!$C$17-((Assumptions!$C$17-Assumptions!$C$19)/5)*(I$7-5)) -> 0.09618 | J17: =IF(J$7<=5,Assumptions!$C$17,Assumptions!$C$17-((Assumptions!$C$17-Assumptions!$C$19)/5)*(J$7-5)) -> 0.09496 | K17: =IF(K$7<=5,Assumptions!$C$17,Assumptions!$C$17-((Assumptions!$C$17-Assumptions!$C$19)/5)*(K$7-5)) -> 0.09374 | ... M17: =IF(M$7<=5,Assumptions!$C$17,Assumptions!$C$17-((Assumptions!$C$17-Assumptions!$C$19)/5)*(M$7-5)) -> 0.0913 | N17: =Assumptions!$C$19 -> 0.0913
B18: Discount factor (cum.) | D18: =1/(1+D17) -> 0.91124476 | E18: =D18/(1+E17) -> 0.83036701 | F18: =E18/(1+F17) -> 0.75666759 | G18: =F18/(1+G17) -> 0.68950938 | H18: =G18/(1+H17) -> 0.62831181 | I18: =H18/(1+I17) -> 0.57318306 | J18: =I18/(1+J17) -> 0.52347397 | K18: =J18/(1+K17) -> 0.47860915 | L18: =K18/(1+L17) -> 0.43807816 | M18: =L18/(1+M17) -> 0.4014278
B19: PV(FCFF) | D19: =D16*D18 -> -10595.699 | E19: =E16*E18 -> -3253.3368 | F19: =F16*F18 -> 2555.8967 | G19: =G16*G18 -> 12061.726 | H19: =H16*H18 -> 34406.946 | I19: =I16*I18 -> 47165.321 | J19: =J16*J18 -> 60491.598 | K19: =K16*K18 -> 72484.138 | ... M19: =M16*M18 -> 72477.675
B21: Terminal value = FCFF_T ÷ (CoC_T − g) | C21: =N16/(N17-N8) -> 3331409.4
B22: PV of terminal value | C22: =C21*M18 -> 1337320.4
B23: PV of FCFF years 1–10 | C23: =SUM(D19:M19) -> 368749.07
B24: Sum of PV | C24: =C22+C23 -> 1706069.4
B25: Value of operating assets = ΣPV×(1−p) + ΣPV×recovery×p | C25: =C24*(1-Assumptions!$C$22)+C24*Assumptions!$C$23*Assumptions!$C$22 -> 1620766
B26: − Debt − PV of commitments + cash + IPO proceeds + non-op assets | C26: =-Assumptions!$C$24-Assumptions!$C$25+Assumptions!$C$26+Assumptions!$C$27+Assumptions!$C$28 -> -256018
B27: Value of equity | C27: =C25+C26 -> 1364748
B28: − Options | C28: =Assumptions!$C$30 -> 472314
B29: Equity to common | C29: =C27-C28 -> 892433.95
B30: Value per share = (equity to common − IPO proceeds) ÷ pre-IPO shares | C30: =(C29-Assumptions!$C$27)/Assumptions!$C$29 -> 257.73563
B31: Post-IPO shares (m) | C31: =Assumptions!$C$29+Assumptions!$C$27/C30 -> 3462.5945
B32: Reference price ÷ value | C32: =Assumptions!$C$31/C30 -> 2.036971
B33: 2036E revenue ($bn) | C33: =M9/1000 -> 967.31699
B34: Year-10 ROIC | C34: =M13/(533836+SUM(D15:L15)) -> 0.22636847
B41: AD block
B42: $m | C42: Base | D42: 2027E | E42: 2028E | F42: 2029E | G42: 2030E | H42: 2031E | I42: 2032E | J42: 2033E | K42: 2034E | L42: 2035E | M42: 2036E | N42: Terminal
B43: t | D43: 1 | E43: 2 | F43: 3 | G43: 4 | H43: 5 | I43: 6 | J43: 7 | K43: 8 | L43: 9 | M43: 10
B44: Revenue growth | D44: =IF(D$43=1,Assumptions!$D$7,IF(D$43<=5,Assumptions!$D$8,Assumptions!$D$8-((Assumptions!$D$8-Assumptions!$D$18)/5)*(D$43-5))) -> 4 | E44: =IF(E$43=1,Assumptions!$D$7,IF(E$43<=5,Assumptions!$D$8,Assumptions!$D$8-((Assumptions!$D$8-Assumptions!$D$18)/5)*(E$43-5))) -> 0.42 | F44: =IF(F$43=1,Assumptions!$D$7,IF(F$43<=5,Assumptions!$D$8,Assumptions!$D$8-((Assumptions!$D$8-Assumptions!$D$18)/5)*(F$43-5))) -> 0.42 | G44: =IF(G$43=1,Assumptions!$D$7,IF(G$43<=5,Assumptions!$D$8,Assumptions!$D$8-((Assumptions!$D$8-Assumptions!$D$18)/5)*(G$43-5))) -> 0.42 | H44: =IF(H$43=1,Assumptions!$D$7,IF(H$43<=5,Assumptions!$D$8,Assumptions!$D$8-((Assumptions!$D$8-Assumptions!$D$18)/5)*(H$43-5))) -> 0.42 | I44: =IF(I$43=1,Assumptions!$D$7,IF(I$43<=5,Assumptions!$D$8,Assumptions!$D$8-((Assumptions!$D$8-Assumptions!$D$18)/5)*(I$43-5))) -> 0.3458 | J44: =IF(J$43=1,Assumptions!$D$7,IF(J$43<=5,Assumptions!$D$8,Assumptions!$D$8-((Assumptions!$D$8-Assumptions!$D$18)/5)*(J$43-5))) -> 0.2716 | K44: =IF(K$43=1,Assumptions!$D$7,IF(K$43<=5,Assumptions!$D$8,Assumptions!$D$8-((Assumptions!$D$8-Assumptions!$D$18)/5)*(K$43-5))) -> 0.1974 | ... M44: =IF(M$43=1,Assumptions!$D$7,IF(M$43<=5,Assumptions!$D$8,Assumptions!$D$8-((Assumptions!$D$8-Assumptions!$D$18)/5)*(M$43-5))) -> 0.049 | N44: =Assumptions!$D$18 -> 0.049
B45: Revenue | C45: =Assumptions!$D$6 -> 20608 | D45: =C45*(1+D44) -> 103040 | E45: =D45*(1+E44) -> 146316.8 | F45: =E45*(1+F44) -> 207769.86 | G45: =F45*(1+G44) -> 295033.2 | H45: =G45*(1+H44) -> 418947.14 | I45: =H45*(1+I44) -> 563819.06 | J45: =I45*(1+J44) -> 716952.31 | K45: =J45*(1+K44) -> 858478.7 | ... N45: =M45*(1+N44) -> 1061054.3
B46: Operating margin | D46: =IF(D$43=1,Assumptions!$D$9,IF(D$43>Assumptions!$D$15,Assumptions!$D$14,Assumptions!$D$14-((Assumptions!$D$14-Assumptions!$D$9)*(Assumptions!$D$15-D$43)/Assumptions!$D$15))) -> 0.05 | E46: =IF(E$43=1,Assumptions!$D$9,IF(E$43>Assumptions!$D$15,Assumptions!$D$14,Assumptions!$D$14-((Assumptions!$D$14-Assumptions!$D$9)*(Assumptions!$D$15-E$43)/Assumptions!$D$15))) -> 0.14 | F46: =IF(F$43=1,Assumptions!$D$9,IF(F$43>Assumptions!$D$15,Assumptions!$D$14,Assumptions!$D$14-((Assumptions!$D$14-Assumptions!$D$9)*(Assumptions!$D$15-F$43)/Assumptions!$D$15))) -> 0.185 | G46: =IF(G$43=1,Assumptions!$D$9,IF(G$43>Assumptions!$D$15,Assumptions!$D$14,Assumptions!$D$14-((Assumptions!$D$14-Assumptions!$D$9)*(Assumptions!$D$15-G$43)/Assumptions!$D$15))) -> 0.23 | H46: =IF(H$43=1,Assumptions!$D$9,IF(H$43>Assumptions!$D$15,Assumptions!$D$14,Assumptions!$D$14-((Assumptions!$D$14-Assumptions!$D$9)*(Assumptions!$D$15-H$43)/Assumptions!$D$15))) -> 0.275 | I46: =IF(I$43=1,Assumptions!$D$9,IF(I$43>Assumptions!$D$15,Assumptions!$D$14,Assumptions!$D$14-((Assumptions!$D$14-Assumptions!$D$9)*(Assumptions!$D$15-I$43)/Assumptions!$D$15))) -> 0.275 | J46: =IF(J$43=1,Assumptions!$D$9,IF(J$43>Assumptions!$D$15,Assumptions!$D$14,Assumptions!$D$14-((Assumptions!$D$14-Assumptions!$D$9)*(Assumptions!$D$15-J$43)/Assumptions!$D$15))) -> 0.275 | K46: =IF(K$43=1,Assumptions!$D$9,IF(K$43>Assumptions!$D$15,Assumptions!$D$14,Assumptions!$D$14-((Assumptions!$D$14-Assumptions!$D$9)*(Assumptions!$D$15-K$43)/Assumptions!$D$15))) -> 0.275 | ... M46: =IF(M$43=1,Assumptions!$D$9,IF(M$43>Assumptions!$D$15,Assumptions!$D$14,Assumptions!$D$14-((Assumptions!$D$14-Assumptions!$D$9)*(Assumptions!$D$15-M$43)/Assumptions!$D$15))) -> 0.275 | N46: =Assumptions!$D$14 -> 0.275
B47: EBIT | D47: =D45*D46 -> 5152 | E47: =E45*E46 -> 20484.352 | F47: =F45*F46 -> 38437.423 | G47: =G45*G46 -> 67857.635 | H47: =H45*H46 -> 115210.46 | I47: =I45*I46 -> 155050.24 | J47: =J45*J46 -> 197161.89 | K47: =K45*K46 -> 236081.64 | ... N47: =N45*N46 -> 291789.92
B48: Tax rate | D48: =IF(D$43<=5,0,Assumptions!$D$21*(D$43-5)/5) -> 0 | E48: =IF(E$43<=5,0,Assumptions!$D$21*(E$43-5)/5) -> 0 | F48: =IF(F$43<=5,0,Assumptions!$D$21*(F$43-5)/5) -> 0 | G48: =IF(G$43<=5,0,Assumptions!$D$21*(G$43-5)/5) -> 0 | H48: =IF(H$43<=5,0,Assumptions!$D$21*(H$43-5)/5) -> 0 | I48: =IF(I$43<=5,0,Assumptions!$D$21*(I$43-5)/5) -> 0.05 | J48: =IF(J$43<=5,0,Assumptions!$D$21*(J$43-5)/5) -> 0.1 | K48: =IF(K$43<=5,0,Assumptions!$D$21*(K$43-5)/5) -> 0.15 | ... M48: =IF(M$43<=5,0,Assumptions!$D$21*(M$43-5)/5) -> 0.25 | N48: =Assumptions!$D$21 -> 0.25
B49: EBIT(1−t) after NOL | D49: =IF(D47>0,IF(D47<C50,D47,D47-(D47-C50)*D48),D47) -> 5152 | E49: =IF(E47>0,IF(E47<D50,E47,E47-(E47-D50)*E48),E47) -> 20484.352 | F49: =IF(F47>0,IF(F47<E50,F47,F47-(F47-E50)*F48),F47) -> 38437.423 | G49: =IF(G47>0,IF(G47<F50,G47,G47-(G47-F50)*G48),G47) -> 67857.635 | H49: =IF(H47>0,IF(H47<G50,H47,H47-(H47-G50)*H48),H47) -> 115210.46 | I49: =IF(I47>0,IF(I47<H50,I47,I47-(I47-H50)*I48),I47) -> 147297.73 | J49: =IF(J47>0,IF(J47<I50,J47,J47-(J47-I50)*J48),J47) -> 177445.7 | K49: =IF(K47>0,IF(K47<J50,K47,K47-(K47-J50)*K48),K47) -> 200669.4 | ... M49: =IF(M47>0,IF(M47<L50,M47,M47-(M47-L50)*M48),M47) -> 208620.06 | N49: =N47*(1-N48) -> 218842.44
B50: NOL carried | C50: 0 | D50: =IF(D47<0,C50-D47,IF(C50>D47,C50-D47,0)) -> 0 | E50: =IF(E47<0,D50-E47,IF(D50>E47,D50-E47,0)) -> 0 | F50: =IF(F47<0,E50-F47,IF(E50>F47,E50-F47,0)) -> 0 | G50: =IF(G47<0,F50-G47,IF(F50>G47,F50-G47,0)) -> 0 | H50: =IF(H47<0,G50-H47,IF(G50>H47,G50-H47,0)) -> 0 | I50: =IF(I47<0,H50-I47,IF(H50>I47,H50-I47,0)) -> 0 | J50: =IF(J47<0,I50-J47,IF(I50>J47,I50-J47,0)) -> 0 | K50: =IF(K47<0,J50-K47,IF(J50>K47,J50-K47,0)) -> 0 | ... M50: =IF(M47<0,L50-M47,IF(L50>M47,L50-M47,0)) -> 0
...

Sheet Scenario
B2: Scenario — probability-weighted value (your ProbTree). Bull and Bear are AD's published cases; Base is each column's own DCF.
B5: Case | C5: Probability (Sameer) | D5: Probability (User) | E5: Equity value, Sameer | F5: Equity value, AD | G5: Equity value, User | H5: Thesis
B6: Bull | C6: 0.25 | D6: 0.25 | E6: =DCF!$C$135 -> 4075766 | F6: =DCF!$C$135 -> 4075766 | G6: =DCF!$C$135 -> 4075766 | H6: AI as industry player: $1.5tn revenue, 40% margin, cheap compute, 7.79% CoC. "Possible, but unlikely" (AD).
B7: Base | C7: 0.5 | D7: 0.5 | E7: =DCF!$C$27 -> 1364748 | F7: =DCF!$C$63 -> 1475878.4 | G7: =DCF!$C$99 -> 1364748 | H7: The column's own DCF.
B8: Bear | C8: 0.25 | D8: 0.25 | E8: =DCF!$C$171 -> -388524.05 | F8: =DCF!$C$171 -> -388524.05 | G8: =DCF!$C$171 -> -388524.05 | H8: AI stays a tool: $200bn revenue, margin −5% after major regulation, scarce compute. Equity below zero.
B9: Check: probabilities sum to 100% | C9: =SUM(C6:C8) -> 1 | D9: =SUM(D6:D8) -> 1
B10: Expected value = Σ probability × equity value | E10: =SUMPRODUCT($C$6:$C$8,E6:E8) -> 1604184.5 | F10: =SUMPRODUCT($C$6:$C$8,F6:F8) -> 1659749.7 | G10: =SUMPRODUCT($D$6:$D$8,G6:G8) -> 1604184.5
B11: Sameer and AD use Sameer's probabilities (column C). User uses column D. Weighting a case with negative equity at 25% is deliberate: the S-1 gives the bear a real mechanism (commitments bill before revenue).

Sheet Relative Valuation
B2: Relative Valuation — comparable price-to-sales (TTM) applied to Anthropic's next-twelve-month revenue
B5: Ticker | C5: Company | D5: Market cap ($m) | E5: Revenue, TTM ($m) | F5: P/S (TTM) | G5: Include? (1/0) | H5: Source / note
B6: MSFT | C6: Microsoft | D6: 3945884 | E6: 331839 | F6: =IF(AND(ISNUMBER(D6),ISNUMBER(E6),E6>0),D6/E6,"n/a") -> 11.890959 | G6: 1 | H6: FY to Jun 2026 revenue; 8-K Ex.99.1 (SEC)
B7: GOOGL | C7: Alphabet | D7: 3899967 | E7: 446320 | F7: =IF(AND(ISNUMBER(D7),ISNUMBER(E7),E7>0),D7/E7,"n/a") -> 8.7380512 | G7: 1 | H7: Sum of four quarters to Jun 2026 (ycharts); Q3 2026 not in hand
B8: META | C8: Meta Platforms | D8: 1585355 | E8: 241600 | F8: =IF(AND(ISNUMBER(D8),ISNUMBER(E8),E8>0),D8/E8,"n/a") -> 6.5618998 | G8: 1 | H8: Sum of four quarters to Sep 2026 (10-Q Q3 2026; ycharts for Q4 2025)
B9: NVDA | C9: Nvidia | D9: 5252354 | E9: 215938 | F9: =IF(AND(ISNUMBER(D9),ISNUMBER(E9),E9>0),D9/E9,"n/a") -> 24.323435 | G9: 1 | H9: FY to Jan 2026 revenue; results release
B10: PLTR | C10: Palantir | D10: 477560 | E10: 8154 | F10: =IF(AND(ISNUMBER(D10),ISNUMBER(E10),E10>0),D10/E10,"n/a") -> 58.567574 | G10: 1 | H10: FY2026 guidance midpoint $8,150–8,158m (Q2 2026 release); TTM not derivable
B12: Median P/S of included comps | F12: {=IFERROR(MEDIAN(IF(($G$6:$G$10=1)*ISNUMBER($F$6:$F$10),$F$6:$F$10)),"pending")} -> 11.890959
B13: Multiple applied (override: leave blank to use the median)
B14: Multiple used | F14: =IF(ISNUMBER(F13),F13,F12) -> 11.890959
B16: Applied to Anthropic | C16: Sameer | D16: AD | E16: User | H16: Reason
B17: NTM revenue = year-1 revenue from each DCF block ($m) | C17: =DCF!$D$9 -> 98540 | D17: =DCF!$D$45 -> 103040 | E17: =DCF!$D$81 -> 98540 | H17: Price-to-sales rather than EV/sales: it needs no net-debt data for the comps and sidesteps how to treat Anthropic's $472bn of capitalised commitments and convertibles. Applied to NTM, not TTM, revenue because Anthropic is growing 5x faster than any comp; even so, the comps' TTM multiple makes no further allowance for growth, so this method is conservative. Sameer's reason for a 30% weight: it anchors to what the market pays today for scaled AI revenue, which the DCF cannot.
B18: × multiple used | C18: =$F$14 -> 11.890959 | D18: =$F$14 -> 11.890959 | E18: =$F$14 -> 11.890959
B19: Relative equity value ($m) = NTM revenue × multiple | C19: =IFERROR(C17*C18,"pending") -> 1171735.1 | D19: =IFERROR(D17*D18,"pending") -> 1225244.4 | E19: =IFERROR(E17*E18,"pending") -> 1171735.1
B24: Public version: market caps from INDmoney US quotes at 29 Oct 2026 08:46 IST; revenues from the filings and sources named per row. Net cash not sourced, hence P/S. NOW, CRM and SNOW left out for want of sourced revenue.

Sheet Sensitivity
B2: Sensitivity — Sameer DCF equity value ($bn). Static values from the Python replica of the DCF (Excel data tables are not portable); the DCF tab is live.
B5: A. 2036 revenue (CAGR yrs 2–5) × target margin
B6: Target margin ↓ / CAGR → | C6: 0.268 | D6: 0.3671 | E6: 0.42 | F6: 0.46 | G6: 0.5125
B7: 0.1 | C7: 2 | D7: 121 | E7: 206 | F7: 281 | G7: 398
B8: 0.175 | C8: 259 | D8: 519 | E8: 702 | F8: 867 | G8: 1121
B9: 0.25 | C9: 517 | D9: 916 | E9: 1199 | F9: 1452 | G9: 1844
B10: 0.275 | C10: 603 | D10: 1049 | E10: 1365 | F10: 1647 | G10: 2084
B11: 0.325 | C11: 774 | D11: 1314 | E11: 1696 | F11: 2038 | G11: 2566
B12: 0.4 | C12: 1032 | D12: 1712 | E12: 2193 | F12: 2623 | G12: 3289
B14: B. Sales to capital × target margin
B15: Target margin ↓ / Sales to capital → | C15: 1 | D15: 1.5 | E15: 2.5 | F15: 3 | G15: 4
B16: 0.1 | C16: -114 | D16: 64 | E16: 206 | F16: 241 | G16: 286
B17: 0.175 | C17: 383 | D17: 560 | E17: 702 | F17: 738 | G17: 782
B18: 0.25 | C18: 880 | D18: 1057 | E18: 1199 | F18: 1235 | G18: 1279
B19: 0.275 | C19: 1045 | D19: 1223 | E19: 1365 | F19: 1400 | G19: 1445
B20: 0.325 | C20: 1376 | D20: 1554 | E20: 1696 | F20: 1731 | G20: 1776
B21: 0.4 | C21: 1873 | D21: 2051 | E21: 2193 | F21: 2228 | G21: 2273
B23: C. Cost of capital × probability of failure
B24: P(fail) ↓ / Cost of capital → | C24: 0.0779 | D24: 0.0916 | E24: 0.0974 | F24: 0.0988 | G24: 0.11
B25: 0 | C25: 1675 | D25: 1514 | E25: 1450 | F25: 1435 | G25: 1320
B26: 0.05 | C26: 1627 | D26: 1470 | E26: 1407 | F26: 1393 | G26: 1281
B27: 0.1 | C27: 1579 | D27: 1425 | E27: 1365 | F27: 1351 | G27: 1242
B28: 0.2 | C28: 1482 | D28: 1337 | E28: 1279 | F28: 1266 | G28: 1163
B29: 0.3 | C29: 1386 | D29: 1248 | E29: 1194 | F29: 1181 | G29: 1084
B31: D. Convergence year × terminal ROIC
B32: Terminal ROIC ↓ / Convergence year → | C32: 3 | D32: 5 | E32: 7 | F32: 10
B33: 0.0913 | C33: 996 | D33: 968 | E33: 926 | F33: 843
B34: 0.12 | C34: 1238 | D34: 1211 | E34: 1168 | F34: 1086
B35: 0.15 | C35: 1393 | D35: 1365 | E35: 1323 | F35: 1240
B36: 0.2 | C36: 1547 | D36: 1519 | E36: 1477 | F36: 1394
B38: E. Tornado: one driver at a time, Sameer base
B39: Driver | C39: Low case | D39: Value ($bn) | E39: High case | F39: Value ($bn) | G39: Swing ($bn)
B40: Target margin | C40: 17.5% | D40: 702 | E40: 32.5% | F40: 1696 | G40: =F40-D40 -> 994
B41: CAGR yrs 2–5 | C41: 36.7% | D41: 1049 | E41: 46% | F41: 1647 | G41: =F41-D41 -> 598
B42: Terminal ROIC | C42: 9.13% | D42: 968 | E42: 20% | F42: 1519 | G42: =F42-D42 -> 551
B43: Sales to capital | C43: 1.5x | D43: 1223 | E43: 4.0x | F43: 1445 | G43: =F43-D43 -> 222
B44: Cost of capital | C44: 10.74% | D44: 1266 | E44: 8.74% | F44: 1471 | G44: =F44-D44 -> 205
B45: PV of commitments | C45: +$100bn | D45: 1265 | E45: −$100bn | F45: 1465 | G45: =F45-D45 -> 200
B46: P(failure) | C46: 20% | D46: 1279 | E46: 0% | F46: 1450 | G46: =F46-D46 -> 171
B47: Sameer base DCF equity: $1,365bn.

Sheet Charts
B2: Charts
B5: Year | C5: Sameer revenue ($bn) | D5: AD revenue ($bn) | E5: User revenue ($bn) | F5: Sameer margin | G5: User margin
B6: 2027E | C6: =DCF!D9/1000 -> 98.54 | D6: =DCF!D45/1000 -> 103.04 | E6: =DCF!D81/1000 -> 98.54 | F6: =DCF!D10 -> 0.05 | G6: =DCF!D82 -> 0.05
B7: 2028E | C7: =DCF!E9/1000 -> 139.9268 | D7: =DCF!E45/1000 -> 146.3168 | E7: =DCF!E81/1000 -> 139.9268 | F7: =DCF!E10 -> 0.14 | G7: =DCF!E82 -> 0.14
B8: 2029E | C8: =DCF!F9/1000 -> 198.69606 | D8: =DCF!F45/1000 -> 207.76986 | E8: =DCF!F81/1000 -> 198.69606 | F8: =DCF!F10 -> 0.185 | G8: =DCF!F82 -> 0.185
B9: 2030E | C9: =DCF!G9/1000 -> 282.1484 | D9: =DCF!G45/1000 -> 295.0332 | E9: =DCF!G81/1000 -> 282.1484 | F9: =DCF!G10 -> 0.23 | G9: =DCF!G82 -> 0.23
B10: 2031E | C10: =DCF!H9/1000 -> 400.65073 | D10: =DCF!H45/1000 -> 418.94714 | E10: =DCF!H81/1000 -> 400.65073 | F10: =DCF!H10 -> 0.275 | G10: =DCF!H82 -> 0.275
B11: 2032E | C11: =DCF!I9/1000 -> 539.19575 | D11: =DCF!I45/1000 -> 563.81906 | E11: =DCF!I81/1000 -> 539.19575 | F11: =DCF!I10 -> 0.275 | G11: =DCF!I82 -> 0.275
B12: 2033E | C12: =DCF!J9/1000 -> 685.64131 | D12: =DCF!J45/1000 -> 716.95231 | E12: =DCF!J81/1000 -> 685.64131 | F12: =DCF!J10 -> 0.275 | G12: =DCF!J82 -> 0.275
B13: 2034E | C13: =DCF!K9/1000 -> 820.98691 | D13: =DCF!K45/1000 -> 858.4787 | E13: =DCF!K81/1000 -> 820.98691 | F13: =DCF!K10 -> 0.275 | G13: =DCF!K82 -> 0.275
B14: 2035E | C14: =DCF!L9/1000 -> 922.1325 | D14: =DCF!L45/1000 -> 964.24328 | E14: =DCF!L81/1000 -> 922.1325 | F14: =DCF!L10 -> 0.275 | G14: =DCF!L82 -> 0.275
B15: 2036E | C15: =DCF!M9/1000 -> 967.31699 | D15: =DCF!M45/1000 -> 1011.4912 | E15: =DCF!M81/1000 -> 967.31699 | F15: =DCF!M10 -> 0.275 | G15: =DCF!M82 -> 0.275
B18: Method | C18: Sameer ($bn) | D18: AD ($bn) | E18: User ($bn)
B19: DCF | C19: =IFERROR('Valuation Summary'!E11,0) -> 1364.748 | D19: =IFERROR('Valuation Summary'!F11,0) -> 1475.8784 | E19: =IFERROR('Valuation Summary'!G11,0) -> 1364.748
B20: Scenario | C20: =IFERROR('Valuation Summary'!E12,0) -> 1604.1845 | D20: =IFERROR('Valuation Summary'!F12,0) -> 1659.7497 | E20: =IFERROR('Valuation Summary'!G12,0) -> 1604.1845
B21: Relative | C21: =IFERROR('Valuation Summary'!E13,0) -> 1171.7351 | D21: =IFERROR('Valuation Summary'!F13,0) -> 1225.2444 | E21: =IFERROR('Valuation Summary'!G13,0) -> 1171.7351
B22: Blended | C22: =IFERROR('Valuation Summary'!H15,0) -> 1378.6751 | D22: =IFERROR('Valuation Summary'!F11,0) -> 1475.8784 | E22: =IFERROR('Valuation Summary'!I15,0) -> 1378.6751
C23: AD "Blended" shows his DCF only.

Sheet Sources
B2: Sources
B5: Anthropic PBC, Form S-1 (preliminary), filed 26 Oct 2026, accession 0001628280-26-067168 | C5: https://www.sec.gov/Archives/edgar/data/2130357/000162828026067168/anthropicpbc-sx1.htm
B6: A. Damodaran, "The Anthropic Prospectus Arrives: My (but not the) IPO valuation!", 28 Oct 2026 | C6: https://aswathdamodaran.blogspot.com/2026/10/the-anthropic-prospectus-arrives-ipo.html
B7: A. Damodaran, AnthropicIPO.xlsx (valuation spreadsheet, 26 Oct 2026), used for the AD column and validated to the dollar
B8: A. Damodaran, "Stock Prices, Earnings and Cashflows: The AI Effect", Oct 2026 | C8: https://aswathdamodaran.blogspot.com/2026/10/stock-prices-earnings-and-cashflows-ai.html
B9: Microsoft 8-K Ex.99.1 FY2026 results (revenue 331,839) | C9: https://www.sec.gov/Archives/edgar/data/0000789019/000119312526323632/msft-ex99_1.htm
B10: Meta 10-Q Q3 2026 (quarterly revenue) | C10: https://www.sec.gov/Archives/edgar/data/0001326801/000162828026066773/meta-20260930.htm
B11: NVIDIA fiscal 2026 results (revenue 215,938) | C11: https://www.storagenewsletter.com/2026/03/04/nvidia-fiscal-4q26-and-fy26-financial-results/
B12: Palantir Q2 2026 release (FY2026 guidance 8,150–8,158) | C12: https://www.sec.gov/Archives/edgar/data/0001321655/000132165526000039/a2026q2ex991pressrelease.htm
B13: Alphabet and Meta quarterly revenue series (ycharts); market caps from INDmoney US quotes, 29 Oct 2026 | C13: https://ycharts.com/companies/GOOGL/revenues
